Workbook
Name AB: [1]BASE!$A:$IV
Name ABC: [1]BASE1!$A:$IV
Name ABCD: #REF!
Name ABCD: #REF!
Name ABCD: #REF!
Name ABVF: [1]GRADO1!$A:$IV
Name ACEPTACIÓN: '[2]PANORAMA RIESGOS'!$BB$13:$BB$42
Name ACT: #REF!
Name ACT: #REF!
Name Actividad: #REF!
Name Actividad: #REF!
Name ACTIVIDADES: #REF!
Name ACTIVIDADES: #REF!
Name BSC: #REF!
Name BSC: #REF!
Name CALIFICACIÓN_CONSECUENCIAS: '[2]PANORAMA RIESGOS'!#REF!
Name CALIFICACIÓN_CONSECUENCIAS: '[2]PANORAMA RIESGOS'!#REF!
Name CALIFICACIÓN_POSIBILIDAD_DE_OCURRENCIA: '[2]PANORAMA RIESGOS'!#REF!
Name Capacidad: [3]Lista!$C$4:$C$8
Name CARACTER: #REF!
Name Clasificación: #REF!
Name Clasificación: #REF!
Name CLASIFICACIÓNCR: #REF!
Name CLASIFICACIÓNCR: #REF!
Name Concepto: [3]Lista!#REF!
Name Concepto_innovación: #REF!
Name Concepto_innovación: #REF!
Name CONSE: #REF!
Name CONSE: #REF!
Name CUMPLIMIENTO_DE_REQUISITOS: '[2]PANORAMA RIESGOS'!#REF!
Name Datos: #REF!
Name Datos: #REF!
Name ECONÓMICO: '[2]PANORAMA RIESGOS'!#REF!
Name ECONÓMICO: '[2]PANORAMA RIESGOS'!#REF!
Name ESCALA: '[4]MATRIZ DE ANALISIS'!$D$10:$D$14
Name EXPOSI: #REF!
Name EXPOSI: #REF!
Name FAC: [5]Hoja1!$B$2:$B$81
Name factor: [5]Hoja1!$B$2:$B$81
Name Horizontes: [3]Lista!$E$4:$E$6
Name IMAGEN: '[2]PANORAMA RIESGOS'!#REF!
Name Impacto: [3]Lista!$D$4:$D$8
Name Índice: #REF!
Name Índice: #REF!
Name Modelo: #REF!
Name Modelo: #REF!
Name NATURALEZA_DE_LA_LESION: #REF!
Name NATURALEZA_DE_LA_LESION: #REF!
Name NATURALEZA_DE_LA_LESION: #REF!
Name NLESION: #REF!
Name NLESION: #REF!
Name ocurrencia: '[4]PANORAMA RIESGOS'!$CC$1:$CD$5
Name OPCIONESM: #REF!
Name OPCIONESM: #REF!
Name OPCIONESM: #REF!
Name OPERATIVIDAD: '[2]PANORAMA RIESGOS'!#REF!
Name OPERATIVIDAD: '[2]PANORAMA RIESGOS'!#REF!
Name PLAC: #REF!
Name PLAC: #REF!
Name PLACAS: #REF!

Sheet CONTROL DE ACTUALIZACIONES 
B1: MATRIZ DE RIESGOS DE SST | D1: MC-ST-FR-92 Version: 00 Fecha: 24/07/2023
A3: CONTROL DE ACTUALIZACIONES
A4: REVISION N° | B4: DESCRIPCION DE LA ACTUALIZACION | C4: FECHA | D4: REALIZADO POR
A5: 0 | B5: Migración a la nueva metodología para la Identificación de peligros, evaluación y valoración de riesgos basada en la ISO 31000, revisada y validada por los líderes del procesos. Se hace la identificación de los peligros y evalúan los riesgos, dando alcance al personal administrativo, que interviene en el proceso de seguridad fisica y proteccion. | C5: 45345 | D5: Enith Moron Ramos

Sheet MATRIZ DE RIESGOS DE SST
C1: MATRIZ DE RIESGOS DE SST | Z1: MC-ST-FR-92 Version: 00 Fecha: 24/07/2023
A2: PROCESO: | B2: DIRECCIÓN DE SEGURIDAD FíSICA Y PROTECCIÓN
A3: FECHA DE ELABORACIÓN: | B3: 45345
A4: ACTIVIDAD/ TAREA | B4: TIPO DE ACTIVIDAD: | D4: EXPUESTOS | H4: CARGO EXPUESTO | I4: FACTOR DE RIESGO (PELIGRO) | J4: CAUSA | K4: CONSECUENCIA | L4: ANÁLISIS DEL RIESGO | Q4: NIVEL DEL RIESGO INHERENTE (Probabilidad x Consecuencia) | R4: CONTROLES ACTUALES | V4: EFICACIA DE(LOS) CONTRO(LES) | W4: % Reducción | X4: VALOR DE RIESGO RESIDUAL | Y4: NIVEL DE RIESGO RESIDUAL | Z4: PLAN DE ACCIÓN
B5: RUTINARIA | C5: NO RUTINARIA | D5: Fijo | E5: Temporal | F5: Contratista | G5: Visitante | J5: GENERADO POR/ CAUSADO POR | K5: POSIBLE EFECTO/ CONSECUENCIA | L5: PROBABILIDAD | M5: Valor probabilidad | N5: CONSECUENCIA | O5: Valor Consecuencia | P5: Valor NRI | R5: En la fuente | S5: En el medio | T5: En la persona | U5: Administrativo
A6: TRABAJOS ADMINISTRATIVOS/ AREA ADMINISTRATIVA | B6: X | D6: X | H6: ANALISTA DE SEGURIDAD ADMINISTRATIVO | I6: BIOLÓGICO: Microorganismos (Virus-COVID-19) | J6: *Contacto directo entre personas portadoras del virus CODIV-19 u objetos contaminados. *Contacto con fluidos corporales y secreciones. | K6: *IRA-Infección Respiratoria Aguda de leve a grave, neumonía, alteraciones en los diferentes sistemas, muerte. | L6: MODERADA | M6: =VLOOKUP('MATRIZ DE RIESGOS DE SST'!L6,'MAPAS DE RIESGOS INHER Y RESID'!$E$3:$F$7,2,FALSE) -> 3 | N6: IMPORTANTE | O6: =VLOOKUP('MATRIZ DE RIESGOS DE SST'!N6,'MAPAS DE RIESGOS INHER Y RESID'!$O$3:$P$7,2,FALSE) -> 16 | P6: =M6*O6 -> 48 | Q6: =IF(OR('MAPAS DE RIESGOS INHER Y RESID'!$G$7='MATRIZ DE RIESGOS DE SST'!P6,P6<'MAPAS DE RIESGOS INHER Y RESID'!$G$3+1),'MAPAS DE RIESGOS INHER Y RESID'!$M$6,IF(OR('MAPAS DE RIESGOS INHER Y RESID'!$H$5='MATRIZ DE RIESGOS DE SST'!P6,P6<'MAPAS DE RIESGOS INHER Y RESID'!$I$5+1),'MAPAS DE RIESGOS INHER Y RESID'!$M$5,IF(OR('MAPAS DE RIESGOS INHER Y RESID'!$I$4='MATRIZ DE RIESGOS DE SST'!P6,P6<'MAPAS DE RIESGOS INHER Y RESID'!$J$4+1),'MAPAS DE RIESGOS INHER Y RESID'!$M$4,'MAPAS DE RIESGOS INHER Y RESID'!$M$3))) -> MODERADO | R6: solicitar el uso de tapabocas a personas con aparentes señales de infección respiratoria | S6: Distanciamiento físico con personas que presenten señales de infección respiratoria | T6: Instar al visitante o funcionario asistir al medico para prueba COVID 19 | U6: aplicación de protocolo de bioseguridad, trabajo flexible en casa para el funcionario | V6: FUERTE | W6: =VLOOKUP(V6,'MAPAS DE RIESGOS INHER Y RESID'!$E$16:$F$18,2,FALSE) -> 0.9 | X6: =P6-(W6*P6) -> 4.8 | Y6: =IF(OR('MAPAS DE RIESGOS INHER Y RESID'!$G$18='MATRIZ DE RIESGOS DE SST'!X6,X6<'MAPAS DE RIESGOS INHER Y RESID'!$G$16+1),'MAPAS DE RIESGOS INHER Y RESID'!$M$19,IF(OR('MAPAS DE RIESGOS INHER Y RESID'!$H$17='MATRIZ DE RIESGOS DE SST'!X6,X6<'MAPAS DE RIESGOS INHER Y RESID'!$I$18+1),'MAPAS DE RIESGOS INHER Y RESID'!$M$18,IF(OR('MAPAS DE RIESGOS INHER Y RESID'!$I$17='MATRIZ DE RIESGOS DE SST'!X6,X6<'MAPAS DE RIESGOS INHER Y RESID'!$J$17+1),'MAPAS DE RIESGOS INHER Y RESID'!$M$17,'MAPAS DE RIESGOS INHER Y RESID'!$M$16))) -> BAJO | Z6: =VLOOKUP('MATRIZ DE RIESGOS DE SST'!Y6,'TABLA DE CRITERIOS'!$A$25:$B$28,2,FALSE) -> Mantener los controles existentes, si se tiene la certeza de que se están cumpliendo los requisitos legales vigentes; en caso contrario, se debe establecer un plan de acción para darle cumplimiento a dichos requisitos, considerando la eliminación o sustitución, si aplica.
I7: BIOMECÁNICO: Movimiento repetitivo | J7: *Digitación. *CAD: Quitar grapas. *Escanear. *Inclinación del cuello al contestar el teléfono y atención al cliente. *Conducción de motocicletas y automóviles. | K7: *Desórdenes de trauma acumulativo; lesiones del sistema músculo esquelético; fatiga; alteraciones lumbares, dorsales, cervicales y sacras; alteraciones del sistema vascular. | L7: BAJA | M7: =VLOOKUP('MATRIZ DE RIESGOS DE SST'!L7,'MAPAS DE RIESGOS INHER Y RESID'!$E$3:$F$7,2,FALSE) -> 2 | N7: LEVE | O7: =VLOOKUP('MATRIZ DE RIESGOS DE SST'!N7,'MAPAS DE RIESGOS INHER Y RESID'!$O$3:$P$7,2,FALSE) -> 4 | P7: =+M7*O7 -> 8 | Q7: =IF(OR('MAPAS DE RIESGOS INHER Y RESID'!$G$7='MATRIZ DE RIESGOS DE SST'!P7,P7<'MAPAS DE RIESGOS INHER Y RESID'!$G$3+1),'MAPAS DE RIESGOS INHER Y RESID'!$M$6,IF(OR('MAPAS DE RIESGOS INHER Y RESID'!$H$5='MATRIZ DE RIESGOS DE SST'!P7,P7<'MAPAS DE RIESGOS INHER Y RESID'!$I$5+1),'MAPAS DE RIESGOS INHER Y RESID'!$M$5,IF(OR('MAPAS DE RIESGOS INHER Y RESID'!$I$4='MATRIZ DE RIESGOS DE SST'!P7,P7<'MAPAS DE RIESGOS INHER Y RESID'!$J$4+1),'MAPAS DE RIESGOS INHER Y RESID'!$M$4,'MAPAS DE RIESGOS INHER Y RESID'!$M$3))) -> BAJO | R7: uso adecuado de elementos de oficina | S7: mantener los elementos de oficina en orden y cuidar de dar mal uso | T7: realizar pausas activas durante la jornada laboral. tener cuidado al momento de utilizar los elementos de oficina que puedan llegar a causar lesión por imprudencia o impericia | U7: realizar mantenimiento de equipos de oficina y reemplazar los que se encuentren averiados | V7: MODERADA | W7: =VLOOKUP(V7,'MAPAS DE RIESGOS INHER Y RESID'!$E$16:$F$18,2,FALSE) -> 0.4 | X7: =P7-(W7*P7) -> 4.8 | Y7: BAJO | Z7: =VLOOKUP('MATRIZ DE RIESGOS DE SST'!Y7,'TABLA DE CRITERIOS'!$A$25:$B$28,2,FALSE) -> Mantener los controles existentes, si se tiene la certeza de que se están cumpliendo los requisitos legales vigentes; en caso contrario, se debe establecer un plan de acción para darle cumplimiento a dichos requisitos, considerando la eliminación o sustitución, si aplica.
I8: BIOMECÁNICO: Postura inadecuada | J8: *Alcanzar objetivos que están ubicados fuera del alcance. *Labores en oficina en general. *Actos inseguros. | K8: *Desórdenes de trauma acumulativo; lesiones del sistema músculo esquelético; fatiga; alteraciones lumbares, dorsales, cervicales y sacras; alteraciones del sistema vascular. | L8: BAJA | M8: =VLOOKUP('MATRIZ DE RIESGOS DE SST'!L8,'MAPAS DE RIESGOS INHER Y RESID'!$E$3:$F$7,2,FALSE) -> 2 | N8: LEVE | O8: =VLOOKUP('MATRIZ DE RIESGOS DE SST'!N8,'MAPAS DE RIESGOS INHER Y RESID'!$O$3:$P$7,2,FALSE) -> 4 | P8: =M8*O8 -> 8 | Q8: =IF(OR('MAPAS DE RIESGOS INHER Y RESID'!$G$7='MATRIZ DE RIESGOS DE SST'!P8,P8<'MAPAS DE RIESGOS INHER Y RESID'!$G$3+1),'MAPAS DE RIESGOS INHER Y RESID'!$M$6,IF(OR('MAPAS DE RIESGOS INHER Y RESID'!$H$5='MATRIZ DE RIESGOS DE SST'!P8,P8<'MAPAS DE RIESGOS INHER Y RESID'!$I$5+1),'MAPAS DE RIESGOS INHER Y RESID'!$M$5,IF(OR('MAPAS DE RIESGOS INHER Y RESID'!$I$4='MATRIZ DE RIESGOS DE SST'!P8,P8<'MAPAS DE RIESGOS INHER Y RESID'!$J$4+1),'MAPAS DE RIESGOS INHER Y RESID'!$M$4,'MAPAS DE RIESGOS INHER Y RESID'!$M$3))) -> BAJO | R8: mantener una buena postura corporal durante las labores , utilizar los medios a disposición para la realización de tareas | S8: solicitar los equipos necesarios y acordes para las tares asignadas | T8: realizar pausas activas durante la jornada laboral. | U8: Dotar de los ELEMENTOS necesarios y acordes a las labores a desempeñar respecto al puesto de trabajo y sus obligaciones | V8: MODERADA | W8: =VLOOKUP(V8,'MAPAS DE RIESGOS INHER Y RESID'!$E$16:$F$18,2,FALSE) -> 0.4 | X8: =P8-(W8*P8) -> 4.8 | Y8: =IF(OR('MAPAS DE RIESGOS INHER Y RESID'!$G$18='MATRIZ DE RIESGOS DE SST'!X8,X8<'MAPAS DE RIESGOS INHER Y RESID'!$G$16+1),'MAPAS DE RIESGOS INHER Y RESID'!$M$19,IF(OR('MAPAS DE RIESGOS INHER Y RESID'!$H$17='MATRIZ DE RIESGOS DE SST'!X8,X8<'MAPAS DE RIESGOS INHER Y RESID'!$I$18+1),'MAPAS DE RIESGOS INHER Y RESID'!$M$18,IF(OR('MAPAS DE RIESGOS INHER Y RESID'!$I$17='MATRIZ DE RIESGOS DE SST'!X8,X8<'MAPAS DE RIESGOS INHER Y RESID'!$J$17+1),'MAPAS DE RIESGOS INHER Y RESID'!$M$17,'MAPAS DE RIESGOS INHER Y RESID'!$M$16))) -> BAJO | Z8: =VLOOKUP('MATRIZ DE RIESGOS DE SST'!Y8,'TABLA DE CRITERIOS'!$A$25:$B$28,2,FALSE) -> Mantener los controles existentes, si se tiene la certeza de que se están cumpliendo los requisitos legales vigentes; en caso contrario, se debe establecer un plan de acción para darle cumplimiento a dichos requisitos, considerando la eliminación o sustitución, si aplica.
I9: FENÓMENOS NATURALES: Terremoto | J9: *Movimientos de tierra. *Excavaciones. | K9: *Contusiones, fracturas, amputaciones, muerte. | L9: BAJA | M9: =VLOOKUP('MATRIZ DE RIESGOS DE SST'!L9,'MAPAS DE RIESGOS INHER Y RESID'!$E$3:$F$7,2,FALSE) -> 2 | N9: IMPORTANTE | O9: =VLOOKUP('MATRIZ DE RIESGOS DE SST'!N9,'MAPAS DE RIESGOS INHER Y RESID'!$O$3:$P$7,2,FALSE) -> 16 | P9: =+M9*O9 -> 32 | Q9: MODERADO | R9: No Aplica. | S9: No Aplica. | T9: suspender actividades y ponerse a salvo | U9: Activar Plan de emergencias y evacuación | V9: MODERADA | W9: =VLOOKUP(V9,'MAPAS DE RIESGOS INHER Y RESID'!$E$16:$F$18,2,FALSE) -> 0.4 | X9: =P9-(W9*P9) -> 19.2 | Y9: =IF(OR('MAPAS DE RIESGOS INHER Y RESID'!$G$18='MATRIZ DE RIESGOS DE SST'!X9,X9<'MAPAS DE RIESGOS INHER Y RESID'!$G$16+1),'MAPAS DE RIESGOS INHER Y RESID'!$M$19,IF(OR('MAPAS DE RIESGOS INHER Y RESID'!$H$17='MATRIZ DE RIESGOS DE SST'!X9,X9<'MAPAS DE RIESGOS INHER Y RESID'!$I$18+1),'MAPAS DE RIESGOS INHER Y RESID'!$M$18,IF(OR('MAPAS DE RIESGOS INHER Y RESID'!$I$17='MATRIZ DE RIESGOS DE SST'!X9,X9<'MAPAS DE RIESGOS INHER Y RESID'!$J$17+1),'MAPAS DE RIESGOS INHER Y RESID'!$M$17,'MAPAS DE RIESGOS INHER Y RESID'!$M$16))) -> MODERADO | Z9: =VLOOKUP('[8]MATRIZ DE RIESGOS DE SST'!Y9,'[8]TABLA DE CRITERIOS'!$A$25:$B$28,2,FALSE) -> Mantener los controles existentes, si se tiene la certeza de que se están cumpliendo los requisitos legales vigentes; en caso contrario, se debe establecer un plan de acción para darle cumplimiento a dichos requisitos, considerando la eliminación o sustitución, si aplica.
I10: FÍSICO: Iluminación excesiva o deficiente | J10: *Luminarias. *Luz natural. *Trabajos Nocturnos | K10: *Fatiga visual, cefalea, disminución de la destreza y precisión, estrés, pérdida de la capacidad de visión | L10: BAJA | M10: =VLOOKUP('MATRIZ DE RIESGOS DE SST'!L10,'MAPAS DE RIESGOS INHER Y RESID'!$E$3:$F$7,2,FALSE) -> 2 | N10: LEVE | O10: =VLOOKUP('MATRIZ DE RIESGOS DE SST'!N10,'MAPAS DE RIESGOS INHER Y RESID'!$O$3:$P$7,2,FALSE) -> 4 | P10: =+M10*O10 -> 8 | Q10: =IF(OR('MAPAS DE RIESGOS INHER Y RESID'!$G$7='MATRIZ DE RIESGOS DE SST'!P10,P10<'MAPAS DE RIESGOS INHER Y RESID'!$G$3+1),'MAPAS DE RIESGOS INHER Y RESID'!$M$6,IF(OR('MAPAS DE RIESGOS INHER Y RESID'!$H$5='MATRIZ DE RIESGOS DE SST'!P10,P10<'MAPAS DE RIESGOS INHER Y RESID'!$I$5+1),'MAPAS DE RIESGOS INHER Y RESID'!$M$5,IF(OR('MAPAS DE RIESGOS INHER Y RESID'!$I$4='MATRIZ DE RIESGOS DE SST'!P10,P10<'MAPAS DE RIESGOS INHER Y RESID'!$J$4+1),'MAPAS DE RIESGOS INHER Y RESID'!$M$4,'MAPAS DE RIESGOS INHER Y RESID'!$M$3))) -> BAJO | R10: Utilizar la iluminación necesaria para desempeñar las labores encomendadas | S10: solicitar la instalación de luminarias con luz acorde al lugar de trabajo | T10: utilizar gafas que protejan del brillo excesivo. | U10: Implementar luminarias acordes al lugar de trabajo | V10: MODERADA | W10: =VLOOKUP(V10,'MAPAS DE RIESGOS INHER Y RESID'!$E$16:$F$18,2,FALSE) -> 0.4 | X10: =P10-(W10*P10) -> 4.8 | Y10: =IF(OR('MAPAS DE RIESGOS INHER Y RESID'!$G$18='MATRIZ DE RIESGOS DE SST'!X10,X10<'MAPAS DE RIESGOS INHER Y RESID'!$G$16+1),'MAPAS DE RIESGOS INHER Y RESID'!$M$19,IF(OR('MAPAS DE RIESGOS INHER Y RESID'!$H$17='MATRIZ DE RIESGOS DE SST'!X10,X10<'MAPAS DE RIESGOS INHER Y RESID'!$I$18+1),'MAPAS DE RIESGOS INHER Y RESID'!$M$18,IF(OR('MAPAS DE RIESGOS INHER Y RESID'!$I$17='MATRIZ DE RIESGOS DE SST'!X10,X10<'MAPAS DE RIESGOS INHER Y RESID'!$J$17+1),'MAPAS DE RIESGOS INHER Y RESID'!$M$17,'MAPAS DE RIESGOS INHER Y RESID'!$M$16))) -> BAJO | Z10: =VLOOKUP('MATRIZ DE RIESGOS DE SST'!Y10,'TABLA DE CRITERIOS'!$A$25:$B$28,2,FALSE) -> Mantener los controles existentes, si se tiene la certeza de que se están cumpliendo los requisitos legales vigentes; en caso contrario, se debe establecer un plan de acción para darle cumplimiento a dichos requisitos, considerando la eliminación o sustitución, si aplica.
I11: FÍSICO: Radiaciones No ionizantes láser, ultravioleta, infrarroja | J11: *Realizar trabajos al aire libre, sol. *Pantallas de computador. *Lámparas. *Sistemas de radiocomunicaciones. *Microondas. | K11: *Alteraciones de la piel, deshidratación, alteración en algunos tejidos blandos (ojos). | L11: BAJA | M11: =VLOOKUP('MATRIZ DE RIESGOS DE SST'!L11,'MAPAS DE RIESGOS INHER Y RESID'!$E$3:$F$7,2,FALSE) -> 2 | N11: LEVE | O11: =VLOOKUP('MATRIZ DE RIESGOS DE SST'!N11,'MAPAS DE RIESGOS INHER Y RESID'!$O$3:$P$7,2,FALSE) -> 4 | P11: =+M11*O11 -> 8 | Q11: =IF(OR('MAPAS DE RIESGOS INHER Y RESID'!$G$7='MATRIZ DE RIESGOS DE SST'!P11,P11<'MAPAS DE RIESGOS INHER Y RESID'!$G$3+1),'MAPAS DE RIESGOS INHER Y RESID'!$M$6,IF(OR('MAPAS DE RIESGOS INHER Y RESID'!$H$5='MATRIZ DE RIESGOS DE SST'!P11,P11<'MAPAS DE RIESGOS INHER Y RESID'!$I$5+1),'MAPAS DE RIESGOS INHER Y RESID'!$M$5,IF(OR('MAPAS DE RIESGOS INHER Y RESID'!$I$4='MATRIZ DE RIESGOS DE SST'!P11,P11<'MAPAS DE RIESGOS INHER Y RESID'!$J$4+1),'MAPAS DE RIESGOS INHER Y RESID'!$M$4,'MAPAS DE RIESGOS INHER Y RESID'!$M$3))) -> BAJO | R11: Emplear los equipos de computo o comunicaciones y de acuerdo a las especificaciones técnicas del fabricante | S11: No Aplica. | T11: utilizar Gafas con filtros para radiaciones UV. | U11: Dar instrucción sobre el manejo adecuado de pantallas de computo y medios de comunicación, realizar pausas activas | V11: FUERTE | W11: =VLOOKUP(V11,'MAPAS DE RIESGOS INHER Y RESID'!$E$16:$F$18,2,FALSE) -> 0.9 | X11: =P11-(W11*P11) -> 0.8 | Y11: =IF(OR('MAPAS DE RIESGOS INHER Y RESID'!$G$18='MATRIZ DE RIESGOS DE SST'!X11,X11<'MAPAS DE RIESGOS INHER Y RESID'!$G$16+1),'MAPAS DE RIESGOS INHER Y RESID'!$M$19,IF(OR('MAPAS DE RIESGOS INHER Y RESID'!$H$17='MATRIZ DE RIESGOS DE SST'!X11,X11<'MAPAS DE RIESGOS INHER Y RESID'!$I$18+1),'MAPAS DE RIESGOS INHER Y RESID'!$M$18,IF(OR('MAPAS DE RIESGOS INHER Y RESID'!$I$17='MATRIZ DE RIESGOS DE SST'!X11,X11<'MAPAS DE RIESGOS INHER Y RESID'!$J$17+1),'MAPAS DE RIESGOS INHER Y RESID'!$M$17,'MAPAS DE RIESGOS INHER Y RESID'!$M$16))) -> BAJO | Z11: =VLOOKUP('MATRIZ DE RIESGOS DE SST'!Y11,'TABLA DE CRITERIOS'!$A$25:$B$28,2,FALSE) -> Mantener los controles existentes, si se tiene la certeza de que se están cumpliendo los requisitos legales vigentes; en caso contrario, se debe establecer un plan de acción para darle cumplimiento a dichos requisitos, considerando la eliminación o sustitución, si aplica.
I12: FÍSICO: Temperaturas extremas frío, calor | J12: *Aires acondicionados. *Altas temperaturas por exposición al sol. *Cambios de temperatura al entrar o salir de la oficina. *Fallas en el aire acondicionado. *Deficiencia de ventilación natural y/o artificial. | K12: *Disconfort térmico. *Afecciones respiratorias, alergias. *Fatiga que puede producir disminución la destreza manual y la rapidez, mareos, desmayos agravamiento de trastornos cardiovasculares. *Deshidratación. | L12: MODERADA | M12: =VLOOKUP('MATRIZ DE RIESGOS DE SST'!L12,'MAPAS DE RIESGOS INHER Y RESID'!$E$3:$F$7,2,FALSE) -> 3 | N12: IMPORTANTE | O12: =VLOOKUP('MATRIZ DE RIESGOS DE SST'!N12,'MAPAS DE RIESGOS INHER Y RESID'!$O$3:$P$7,2,FALSE) -> 16 | P12: =+M12*O12 -> 48 | Q12: =IF(OR('MAPAS DE RIESGOS INHER Y RESID'!$G$7='MATRIZ DE RIESGOS DE SST'!P12,P12<'MAPAS DE RIESGOS INHER Y RESID'!$G$3+1),'MAPAS DE RIESGOS INHER Y RESID'!$M$6,IF(OR('MAPAS DE RIESGOS INHER Y RESID'!$H$5='MATRIZ DE RIESGOS DE SST'!P12,P12<'MAPAS DE RIESGOS INHER Y RESID'!$I$5+1),'MAPAS DE RIESGOS INHER Y RESID'!$M$5,IF(OR('MAPAS DE RIESGOS INHER Y RESID'!$I$4='MATRIZ DE RIESGOS DE SST'!P12,P12<'MAPAS DE RIESGOS INHER Y RESID'!$J$4+1),'MAPAS DE RIESGOS INHER Y RESID'!$M$4,'MAPAS DE RIESGOS INHER Y RESID'!$M$3))) -> MODERADO | R12: Mantener los aires acondicionados en una temperatura acorde y confortable | S12: Realizar análisis de temperatura necesaria para el mantenimiento optimo de equipos | T12: utilizar ropa abrigada de ser necesario | U12: Mantenimiento de los equipos e aires acondicionados | V12: FUERTE | W12: =VLOOKUP(V12,'MAPAS DE RIESGOS INHER Y RESID'!$E$16:$F$18,2,FALSE) -> 0.9 | X12: =P12-(W12*P12) -> 4.8 | Y12: MODERADO | Z12: =VLOOKUP('MATRIZ DE RIESGOS DE SST'!Y12,'TABLA DE CRITERIOS'!$A$25:$B$28,2,FALSE) -> Reforzar la divulgación y aplicación de los controles existentes para mejorar su eficacia o complementar dichos controles estableciendo el plan de acción necesario, teniendo en cuenta la jerarquía de definición de controles.
I13: SEGURIDAD: Eléctrico-Equipos energizados (alta o baja) | J13: *Contacto con tomacorrientes. *Uso de extensión eléctricas defectuosas. *Construcción de energía fotovoltaica. | K13: *Electrocución, paro cardiaco, paro respiratorio, fibrilación ventricular, tetanización, quemaduras severas, shock eléctrico, muerte. *Golpes, heridas, fracturas, atrapamientos, electrocución, quemaduras, muerte. | L13: BAJA | M13: =VLOOKUP('MATRIZ DE RIESGOS DE SST'!L13,'MAPAS DE RIESGOS INHER Y RESID'!$E$3:$F$7,2,FALSE) -> 2 | N13: LEVE | O13: =VLOOKUP('MATRIZ DE RIESGOS DE SST'!N13,'MAPAS DE RIESGOS INHER Y RESID'!$O$3:$P$7,2,FALSE) -> 4 | P13: =+M13*O13 -> 8 | Q13: =IF(OR('MAPAS DE RIESGOS INHER Y RESID'!$G$7='MATRIZ DE RIESGOS DE SST'!P13,P13<'MAPAS DE RIESGOS INHER Y RESID'!$G$3+1),'MAPAS DE RIESGOS INHER Y RESID'!$M$6,IF(OR('MAPAS DE RIESGOS INHER Y RESID'!$H$5='MATRIZ DE RIESGOS DE SST'!P13,P13<'MAPAS DE RIESGOS INHER Y RESID'!$I$5+1),'MAPAS DE RIESGOS INHER Y RESID'!$M$5,IF(OR('MAPAS DE RIESGOS INHER Y RESID'!$I$4='MATRIZ DE RIESGOS DE SST'!P13,P13<'MAPAS DE RIESGOS INHER Y RESID'!$J$4+1),'MAPAS DE RIESGOS INHER Y RESID'!$M$4,'MAPAS DE RIESGOS INHER Y RESID'!$M$3))) -> BAJO | R13: Realizar verificación visual de equipos eléctricos, cables y tomacorrientes antes de conectar y utilizar | S13: no tratar de arreglar tomacorrientes dañados, cambiar luminarias defectuosas | T13: no aplica | U13: Solicitar el mantenimiento técnico de tomacorrientes, cabes o luminarias con daños y desperfectos | V13: MODERADA | W13: =VLOOKUP(V13,'MAPAS DE RIESGOS INHER Y RESID'!$E$16:$F$18,2,FALSE) -> 0.4 | X13: =P13-(W13*P13) -> 4.8 | Y13: =IF(OR('MAPAS DE RIESGOS INHER Y RESID'!$G$18='MATRIZ DE RIESGOS DE SST'!X13,X13<'MAPAS DE RIESGOS INHER Y RESID'!$G$16+1),'MAPAS DE RIESGOS INHER Y RESID'!$M$19,IF(OR('MAPAS DE RIESGOS INHER Y RESID'!$H$17='MATRIZ DE RIESGOS DE SST'!X13,X13<'MAPAS DE RIESGOS INHER Y RESID'!$I$18+1),'MAPAS DE RIESGOS INHER Y RESID'!$M$18,IF(OR('MAPAS DE RIESGOS INHER Y RESID'!$I$17='MATRIZ DE RIESGOS DE SST'!X13,X13<'MAPAS DE RIESGOS INHER Y RESID'!$J$17+1),'MAPAS DE RIESGOS INHER Y RESID'!$M$17,'MAPAS DE RIESGOS INHER Y RESID'!$M$16))) -> BAJO | Z13: =VLOOKUP('MATRIZ DE RIESGOS DE SST'!Y13,'TABLA DE CRITERIOS'!$A$25:$B$28,2,FALSE) -> Mantener los controles existentes, si se tiene la certeza de que se están cumpliendo los requisitos legales vigentes; en caso contrario, se debe establecer un plan de acción para darle cumplimiento a dichos requisitos, considerando la eliminación o sustitución, si aplica.
I14: SEGURIDAD: Mecánico-Contacto con objetos cortantes / Punzantes | J14: *Uso de elementos de oficina: Ganchos legajadores, hojas, grapas, guillotina, exactos, bisturí, etc. *Uso de herramientas de corte (segueta, pinzas, etc.) *Superficies de trabajo con residuos cortantes y/o punzantes. *Manipulación de materiales de trabajo. | K14: *Heridas, amputaciones, trastornos de tejidos blandos. | L14: BAJA | M14: =VLOOKUP('MATRIZ DE RIESGOS DE SST'!L14,'MAPAS DE RIESGOS INHER Y RESID'!$E$3:$F$7,2,FALSE) -> 2 | N14: LEVE | O14: =VLOOKUP('MATRIZ DE RIESGOS DE SST'!N14,'MAPAS DE RIESGOS INHER Y RESID'!$O$3:$P$7,2,FALSE) -> 4 | P14: =+M14*O14 -> 8 | Q14: =IF(OR('MAPAS DE RIESGOS INHER Y RESID'!$G$7='MATRIZ DE RIESGOS DE SST'!P14,P14<'MAPAS DE RIESGOS INHER Y RESID'!$G$3+1),'MAPAS DE RIESGOS INHER Y RESID'!$M$6,IF(OR('MAPAS DE RIESGOS INHER Y RESID'!$H$5='MATRIZ DE RIESGOS DE SST'!P14,P14<'MAPAS DE RIESGOS INHER Y RESID'!$I$5+1),'MAPAS DE RIESGOS INHER Y RESID'!$M$5,IF(OR('MAPAS DE RIESGOS INHER Y RESID'!$I$4='MATRIZ DE RIESGOS DE SST'!P14,P14<'MAPAS DE RIESGOS INHER Y RESID'!$J$4+1),'MAPAS DE RIESGOS INHER Y RESID'!$M$4,'MAPAS DE RIESGOS INHER Y RESID'!$M$3))) -> BAJO | R14: uso adecuado de elementos de oficina | S14: mantener los elementos de oficina en orden y cuidar de dar mal uso | T14: realizar pausas activas durante la jornada laboral. tener cuidado al momento de utilizar los elementos de oficina que puedan llegar a causar lesión por imprudencia o impericia | U14: realizar mantenimiento de equipos de oficina y reemplazar los que se encuentren averiados | V14: MODERADA | W14: =VLOOKUP(V14,'MAPAS DE RIESGOS INHER Y RESID'!$E$16:$F$18,2,FALSE) -> 0.4 | X14: =P14-(P14*W14) -> 4.8 | Y14: =IF(OR('MAPAS DE RIESGOS INHER Y RESID'!$G$18='MATRIZ DE RIESGOS DE SST'!X14,X14<'MAPAS DE RIESGOS INHER Y RESID'!$G$16+1),'MAPAS DE RIESGOS INHER Y RESID'!$M$19,IF(OR('MAPAS DE RIESGOS INHER Y RESID'!$H$17='MATRIZ DE RIESGOS DE SST'!X14,X14<'MAPAS DE RIESGOS INHER Y RESID'!$I$18+1),'MAPAS DE RIESGOS INHER Y RESID'!$M$18,IF(OR('MAPAS DE RIESGOS INHER Y RESID'!$I$17='MATRIZ DE RIESGOS DE SST'!X14,X14<'MAPAS DE RIESGOS INHER Y RESID'!$J$17+1),'MAPAS DE RIESGOS INHER Y RESID'!$M$17,'MAPAS DE RIESGOS INHER Y RESID'!$M$16))) -> BAJO | Z14: =VLOOKUP('MATRIZ DE RIESGOS DE SST'!Y14,'TABLA DE CRITERIOS'!$A$25:$B$28,2,FALSE) -> Mantener los controles existentes, si se tiene la certeza de que se están cumpliendo los requisitos legales vigentes; en caso contrario, se debe establecer un plan de acción para darle cumplimiento a dichos requisitos, considerando la eliminación o sustitución, si aplica.
I15: BIOMECÁNICO: Postura prolongada mantenida | J15: *Labores en oficina en general. | K15: *Desórdenes de trauma acumulativo; lesiones del sistema músculo esquelético; fatiga; alteraciones lumbares, dorsales, cervicales y sacras; alteraciones del sistema vascular. | L15: MODERADA | M15: =VLOOKUP('MATRIZ DE RIESGOS DE SST'!L15,'MAPAS DE RIESGOS INHER Y RESID'!$E$3:$F$7,2,FALSE) -> 3 | N15: IMPORTANTE | O15: =VLOOKUP('MATRIZ DE RIESGOS DE SST'!N15,'MAPAS DE RIESGOS INHER Y RESID'!$O$3:$P$7,2,FALSE) -> 16 | P15: =+M15*O15 -> 48 | Q15: ALTO | R15: espacio adecuado de trabajo, mobiliario ergonómico (sillas, descansa pies y teclados para computador) archivadores organizadores | S15: No Aplica | T15: Hacer pausas activas durante la jornada laboral | U15: solicitar acompañamiento y evaluación de seguridad y salud en el trabajo | V15: FUERTE | W15: =VLOOKUP(V15,'MAPAS DE RIESGOS INHER Y RESID'!$E$16:$F$18,2,FALSE) -> 0.9 | X15: =P15-(P15*W15) -> 4.8 | Y15: BAJO | Z15: =VLOOKUP('MATRIZ DE RIESGOS DE SST'!Y15,'TABLA DE CRITERIOS'!$A$25:$B$28,2,FALSE) -> Mantener los controles existentes, si se tiene la certeza de que se están cumpliendo los requisitos legales vigentes; en caso contrario, se debe establecer un plan de acción para darle cumplimiento a dichos requisitos, considerando la eliminación o sustitución, si aplica.
A16: TRABAJOS ADMINISTRATIVOS/ AREA ADMINISTRATIVA | B16: X | D16: X | H16: DIRECTOR DE SEGURIDAD | I16: BIOLÓGICO: Microorganismos (Virus-COVID-19) | J16: *Contacto directo entre personas portadoras del virus CODIV-19 u objetos contaminados. *Contacto con fluidos corporales y secreciones. | K16: *IRA-Infección Respiratoria Aguda de leve a grave, neumonía, alteraciones en los diferentes sistemas, muerte. | L16: MODERADA | M16: =VLOOKUP('MATRIZ DE RIESGOS DE SST'!L16,'MAPAS DE RIESGOS INHER Y RESID'!$E$3:$F$7,2,FALSE) -> 3 | N16: IMPORTANTE | O16: =VLOOKUP('MATRIZ DE RIESGOS DE SST'!N16,'MAPAS DE RIESGOS INHER Y RESID'!$O$3:$P$7,2,FALSE) -> 16 | P16: =M16*O16 -> 48 | Q16: =IF(OR('MAPAS DE RIESGOS INHER Y RESID'!$G$7='MATRIZ DE RIESGOS DE SST'!P16,P16<'MAPAS DE RIESGOS INHER Y RESID'!$G$3+1),'MAPAS DE RIESGOS INHER Y RESID'!$M$6,IF(OR('MAPAS DE RIESGOS INHER Y RESID'!$H$5='MATRIZ DE RIESGOS DE SST'!P16,P16<'MAPAS DE RIESGOS INHER Y RESID'!$I$5+1),'MAPAS DE RIESGOS INHER Y RESID'!$M$5,IF(OR('MAPAS DE RIESGOS INHER Y RESID'!$I$4='MATRIZ DE RIESGOS DE SST'!P16,P16<'MAPAS DE RIESGOS INHER Y RESID'!$J$4+1),'MAPAS DE RIESGOS INHER Y RESID'!$M$4,'MAPAS DE RIESGOS INHER Y RESID'!$M$3))) -> MODERADO | R16: solicitar el uso de tapabocas a personas con aparentes señales de infección respiratoria | S16: Distanciamiento físico con personas que presenten señales de infección respiratoria | T16: Instar al visitante o funcionario asistir al medico para prueba COVID 19 | U16: aplicación de protocolo de bioseguridad, trabajo flexible en casa para el funcionario | V16: FUERTE | W16: =VLOOKUP(V16,'MAPAS DE RIESGOS INHER Y RESID'!$E$16:$F$18,2,FALSE) -> 0.9 | X16: =P16-(W16*P16) -> 4.8 | Y16: =IF(OR('MAPAS DE RIESGOS INHER Y RESID'!$G$18='MATRIZ DE RIESGOS DE SST'!X16,X16<'MAPAS DE RIESGOS INHER Y RESID'!$G$16+1),'MAPAS DE RIESGOS INHER Y RESID'!$M$19,IF(OR('MAPAS DE RIESGOS INHER Y RESID'!$H$17='MATRIZ DE RIESGOS DE SST'!X16,X16<'MAPAS DE RIESGOS INHER Y RESID'!$I$18+1),'MAPAS DE RIESGOS INHER Y RESID'!$M$18,IF(OR('MAPAS DE RIESGOS INHER Y RESID'!$I$17='MATRIZ DE RIESGOS DE SST'!X16,X16<'MAPAS DE RIESGOS INHER Y RESID'!$J$17+1),'MAPAS DE RIESGOS INHER Y RESID'!$M$17,'MAPAS DE RIESGOS INHER Y RESID'!$M$16))) -> BAJO | Z16: =VLOOKUP('MATRIZ DE RIESGOS DE SST'!Y16,'TABLA DE CRITERIOS'!$A$25:$B$28,2,FALSE) -> Mantener los controles existentes, si se tiene la certeza de que se están cumpliendo los requisitos legales vigentes; en caso contrario, se debe establecer un plan de acción para darle cumplimiento a dichos requisitos, considerando la eliminación o sustitución, si aplica.
I17: BIOMECÁNICO: Postura inadecuada | J17: *Alcanzar objetivos que están ubicados fuera del alcance. *Labores en oficina en general. *Actos inseguros. | K17: *Desórdenes de trauma acumulativo; lesiones del sistema músculo esquelético; fatiga; alteraciones lumbares, dorsales, cervicales y sacras; alteraciones del sistema vascular. | L17: BAJA | M17: =VLOOKUP('MATRIZ DE RIESGOS DE SST'!L17,'MAPAS DE RIESGOS INHER Y RESID'!$E$3:$F$7,2,FALSE) -> 2 | N17: LEVE | O17: =VLOOKUP('MATRIZ DE RIESGOS DE SST'!N17,'MAPAS DE RIESGOS INHER Y RESID'!$O$3:$P$7,2,FALSE) -> 4 | P17: =M17*O17 -> 8 | Q17: =IF(OR('MAPAS DE RIESGOS INHER Y RESID'!$G$7='MATRIZ DE RIESGOS DE SST'!P17,P17<'MAPAS DE RIESGOS INHER Y RESID'!$G$3+1),'MAPAS DE RIESGOS INHER Y RESID'!$M$6,IF(OR('MAPAS DE RIESGOS INHER Y RESID'!$H$5='MATRIZ DE RIESGOS DE SST'!P17,P17<'MAPAS DE RIESGOS INHER Y RESID'!$I$5+1),'MAPAS DE RIESGOS INHER Y RESID'!$M$5,IF(OR('MAPAS DE RIESGOS INHER Y RESID'!$I$4='MATRIZ DE RIESGOS DE SST'!P17,P17<'MAPAS DE RIESGOS INHER Y RESID'!$J$4+1),'MAPAS DE RIESGOS INHER Y RESID'!$M$4,'MAPAS DE RIESGOS INHER Y RESID'!$M$3))) -> BAJO | R17: mantener una buena postura corporal durante las labores , utilizar los medios a disposición para la realización de tareas | S17: solicitar los equipos necesarios y acordes para las tares asignadas | T17: realizar pausas activas durante la jornada laboral. | U17: Dotar de los ELEMENTOS necesarios y acordes a las labores a desempeñar respecto al puesto de trabajo y sus obligaciones | V17: MODERADA | W17: =VLOOKUP(V17,'MAPAS DE RIESGOS INHER Y RESID'!$E$16:$F$18,2,FALSE) -> 0.4 | X17: =P17-(W17*P17) -> 4.8 | Y17: =IF(OR('MAPAS DE RIESGOS INHER Y RESID'!$G$18='MATRIZ DE RIESGOS DE SST'!X17,X17<'MAPAS DE RIESGOS INHER Y RESID'!$G$16+1),'MAPAS DE RIESGOS INHER Y RESID'!$M$19,IF(OR('MAPAS DE RIESGOS INHER Y RESID'!$H$17='MATRIZ DE RIESGOS DE SST'!X17,X17<'MAPAS DE RIESGOS INHER Y RESID'!$I$18+1),'MAPAS DE RIESGOS INHER Y RESID'!$M$18,IF(OR('MAPAS DE RIESGOS INHER Y RESID'!$I$17='MATRIZ DE RIESGOS DE SST'!X17,X17<'MAPAS DE RIESGOS INHER Y RESID'!$J$17+1),'MAPAS DE RIESGOS INHER Y RESID'!$M$17,'MAPAS DE RIESGOS INHER Y RESID'!$M$16))) -> BAJO | Z17: =VLOOKUP('MATRIZ DE RIESGOS DE SST'!Y17,'TABLA DE CRITERIOS'!$A$25:$B$28,2,FALSE) -> Mantener los controles existentes, si se tiene la certeza de que se están cumpliendo los requisitos legales vigentes; en caso contrario, se debe establecer un plan de acción para darle cumplimiento a dichos requisitos, considerando la eliminación o sustitución, si aplica.
I18: FENÓMENOS NATURALES: Terremoto | J18: *Movimientos de tierra. *Excavaciones. | K18: *Contusiones, fracturas, amputaciones, muerte. | L18: BAJA | M18: =VLOOKUP('MATRIZ DE RIESGOS DE SST'!L18,'MAPAS DE RIESGOS INHER Y RESID'!$E$3:$F$7,2,FALSE) -> 2 | N18: IMPORTANTE | O18: =VLOOKUP('MATRIZ DE RIESGOS DE SST'!N18,'MAPAS DE RIESGOS INHER Y RESID'!$O$3:$P$7,2,FALSE) -> 16 | P18: =+M18*O18 -> 32 | Q18: MODERADO | R18: No Aplica. | S18: No Aplica. | T18: suspender actividades y ponerse a salvo | U18: Activar Plan de emergencias y evacuación | V18: MODERADA | W18: =VLOOKUP(V18,'MAPAS DE RIESGOS INHER Y RESID'!$E$16:$F$18,2,FALSE) -> 0.4 | X18: =P18-(W18*P18) -> 19.2 | Y18: =IF(OR('MAPAS DE RIESGOS INHER Y RESID'!$G$18='MATRIZ DE RIESGOS DE SST'!X18,X18<'MAPAS DE RIESGOS INHER Y RESID'!$G$16+1),'MAPAS DE RIESGOS INHER Y RESID'!$M$19,IF(OR('MAPAS DE RIESGOS INHER Y RESID'!$H$17='MATRIZ DE RIESGOS DE SST'!X18,X18<'MAPAS DE RIESGOS INHER Y RESID'!$I$18+1),'MAPAS DE RIESGOS INHER Y RESID'!$M$18,IF(OR('MAPAS DE RIESGOS INHER Y RESID'!$I$17='MATRIZ DE RIESGOS DE SST'!X18,X18<'MAPAS DE RIESGOS INHER Y RESID'!$J$17+1),'MAPAS DE RIESGOS INHER Y RESID'!$M$17,'MAPAS DE RIESGOS INHER Y RESID'!$M$16))) -> MODERADO | Z18: =VLOOKUP('MATRIZ DE RIESGOS DE SST'!Y18,'TABLA DE CRITERIOS'!$A$25:$B$28,2,FALSE) -> Reforzar la divulgación y aplicación de los controles existentes para mejorar su eficacia o complementar dichos controles estableciendo el plan de acción necesario, teniendo en cuenta la jerarquía de definición de controles.
I19: FÍSICO: Iluminación excesiva o deficiente | J19: *Luminarias. *Luz natural. *Trabajos Nocturnos | K19: *Fatiga visual, cefalea, disminución de la destreza y precisión, estrés, pérdida de la capacidad de visión | L19: BAJA | M19: =VLOOKUP('MATRIZ DE RIESGOS DE SST'!L19,'MAPAS DE RIESGOS INHER Y RESID'!$E$3:$F$7,2,FALSE) -> 2 | N19: LEVE | O19: =VLOOKUP('MATRIZ DE RIESGOS DE SST'!N19,'MAPAS DE RIESGOS INHER Y RESID'!$O$3:$P$7,2,FALSE) -> 4 | P19: =+M19*O19 -> 8 | Q19: =IF(OR('MAPAS DE RIESGOS INHER Y RESID'!$G$7='MATRIZ DE RIESGOS DE SST'!P19,P19<'MAPAS DE RIESGOS INHER Y RESID'!$G$3+1),'MAPAS DE RIESGOS INHER Y RESID'!$M$6,IF(OR('MAPAS DE RIESGOS INHER Y RESID'!$H$5='MATRIZ DE RIESGOS DE SST'!P19,P19<'MAPAS DE RIESGOS INHER Y RESID'!$I$5+1),'MAPAS DE RIESGOS INHER Y RESID'!$M$5,IF(OR('MAPAS DE RIESGOS INHER Y RESID'!$I$4='MATRIZ DE RIESGOS DE SST'!P19,P19<'MAPAS DE RIESGOS INHER Y RESID'!$J$4+1),'MAPAS DE RIESGOS INHER Y RESID'!$M$4,'MAPAS DE RIESGOS INHER Y RESID'!$M$3))) -> BAJO | R19: Utilizar la iluminación necesaria para desempeñar las labores encomendadas | S19: solicitar la instalación de luminarias con luz acorde al lugar de trabajo | T19: utilizar gafas que protejan del brillo excesivo. | U19: Implementar luminarias acordes al lugar de trabajo | V19: MODERADA | W19: =VLOOKUP(V19,'MAPAS DE RIESGOS INHER Y RESID'!$E$16:$F$18,2,FALSE) -> 0.4 | X19: =P19-(W19*P19) -> 4.8 | Y19: =IF(OR('MAPAS DE RIESGOS INHER Y RESID'!$G$18='MATRIZ DE RIESGOS DE SST'!X19,X19<'MAPAS DE RIESGOS INHER Y RESID'!$G$16+1),'MAPAS DE RIESGOS INHER Y RESID'!$M$19,IF(OR('MAPAS DE RIESGOS INHER Y RESID'!$H$17='MATRIZ DE RIESGOS DE SST'!X19,X19<'MAPAS DE RIESGOS INHER Y RESID'!$I$18+1),'MAPAS DE RIESGOS INHER Y RESID'!$M$18,IF(OR('MAPAS DE RIESGOS INHER Y RESID'!$I$17='MATRIZ DE RIESGOS DE SST'!X19,X19<'MAPAS DE RIESGOS INHER Y RESID'!$J$17+1),'MAPAS DE RIESGOS INHER Y RESID'!$M$17,'MAPAS DE RIESGOS INHER Y RESID'!$M$16))) -> BAJO | Z19: =VLOOKUP('MATRIZ DE RIESGOS DE SST'!Y19,'TABLA DE CRITERIOS'!$A$25:$B$28,2,FALSE) -> Mantener los controles existentes, si se tiene la certeza de que se están cumpliendo los requisitos legales vigentes; en caso contrario, se debe establecer un plan de acción para darle cumplimiento a dichos requisitos, considerando la eliminación o sustitución, si aplica.
I20: FÍSICO: Temperaturas extremas frío, calor | J20: *Aires acondicionados. *Altas temperaturas por exposición al sol. *Cambios de temperatura al entrar o salir de la oficina. *Fallas en el aire acondicionado. *Deficiencia de ventilación natural y/o artificial. | K20: *Disconfort térmico. *Afecciones respiratorias, alergias. *Fatiga que puede producir disminución la destreza manual y la rapidez, mareos, desmayos agravamiento de trastornos cardiovasculares. *Deshidratación. | L20: MODERADA | M20: =VLOOKUP('MATRIZ DE RIESGOS DE SST'!L20,'MAPAS DE RIESGOS INHER Y RESID'!$E$3:$F$7,2,FALSE) -> 3 | N20: IMPORTANTE | O20: =VLOOKUP('MATRIZ DE RIESGOS DE SST'!N20,'MAPAS DE RIESGOS INHER Y RESID'!$O$3:$P$7,2,FALSE) -> 16 | P20: =+M20*O20 -> 48 | Q20: =IF(OR('MAPAS DE RIESGOS INHER Y RESID'!$G$7='MATRIZ DE RIESGOS DE SST'!P20,P20<'MAPAS DE RIESGOS INHER Y RESID'!$G$3+1),'MAPAS DE RIESGOS INHER Y RESID'!$M$6,IF(OR('MAPAS DE RIESGOS INHER Y RESID'!$H$5='MATRIZ DE RIESGOS DE SST'!P20,P20<'MAPAS DE RIESGOS INHER Y RESID'!$I$5+1),'MAPAS DE RIESGOS INHER Y RESID'!$M$5,IF(OR('MAPAS DE RIESGOS INHER Y RESID'!$I$4='MATRIZ DE RIESGOS DE SST'!P20,P20<'MAPAS DE RIESGOS INHER Y RESID'!$J$4+1),'MAPAS DE RIESGOS INHER Y RESID'!$M$4,'MAPAS DE RIESGOS INHER Y RESID'!$M$3))) -> MODERADO | R20: Mantener los aires acondicionados en una temperatura acorde y confortable | S20: Realizar análisis de temperatura necesaria para el mantenimiento optimo de equipos | T20: utilizar ropa abrigada de ser necesario | U20: Mantenimiento de los equipos e aires acondicionados | V20: FUERTE | W20: =VLOOKUP(V20,'MAPAS DE RIESGOS INHER Y RESID'!$E$16:$F$18,2,FALSE) -> 0.9 | X20: =P20-(W20*P20) -> 4.8 | Y20: MODERADO | Z20: =VLOOKUP('MATRIZ DE RIESGOS DE SST'!Y20,'TABLA DE CRITERIOS'!$A$25:$B$28,2,FALSE) -> Reforzar la divulgación y aplicación de los controles existentes para mejorar su eficacia o complementar dichos controles estableciendo el plan de acción necesario, teniendo en cuenta la jerarquía de definición de controles.
I21: SEGURIDAD: Eléctrico-Equipos energizados (alta o baja) | J21: *Contacto con tomacorrientes. *Uso de extensión eléctricas defectuosas. *Construcción de energía fotovoltaica. | K21: *Electrocución, paro cardiaco, paro respiratorio, fibrilación ventricular, tetanización, quemaduras severas, shock eléctrico, muerte. *Golpes, heridas, fracturas, atrapamientos, electrocución, quemaduras, muerte. | L21: BAJA | M21: =VLOOKUP('MATRIZ DE RIESGOS DE SST'!L21,'MAPAS DE RIESGOS INHER Y RESID'!$E$3:$F$7,2,FALSE) -> 2 | N21: LEVE | O21: =VLOOKUP('MATRIZ DE RIESGOS DE SST'!N21,'MAPAS DE RIESGOS INHER Y RESID'!$O$3:$P$7,2,FALSE) -> 4 | P21: =+M21*O21 -> 8 | Q21: =IF(OR('MAPAS DE RIESGOS INHER Y RESID'!$G$7='MATRIZ DE RIESGOS DE SST'!P21,P21<'MAPAS DE RIESGOS INHER Y RESID'!$G$3+1),'MAPAS DE RIESGOS INHER Y RESID'!$M$6,IF(OR('MAPAS DE RIESGOS INHER Y RESID'!$H$5='MATRIZ DE RIESGOS DE SST'!P21,P21<'MAPAS DE RIESGOS INHER Y RESID'!$I$5+1),'MAPAS DE RIESGOS INHER Y RESID'!$M$5,IF(OR('MAPAS DE RIESGOS INHER Y RESID'!$I$4='MATRIZ DE RIESGOS DE SST'!P21,P21<'MAPAS DE RIESGOS INHER Y RESID'!$J$4+1),'MAPAS DE RIESGOS INHER Y RESID'!$M$4,'MAPAS DE RIESGOS INHER Y RESID'!$M$3))) -> BAJO | R21: Realizar verificación visual de equipos eléctricos, cables y tomacorrientes antes de conectar y utilizar | S21: no manipular tomacorrientes, equipos o luminarias defectuosas | T21: no aplica | U21: Solicitar el mantenimiento técnico de tomacorrientes, cabes o luminarias con daños y desperfectos | V21: MODERADA | W21: =VLOOKUP(V21,'MAPAS DE RIESGOS INHER Y RESID'!$E$16:$F$18,2,FALSE) -> 0.4 | X21: =P21-(W21*P21) -> 4.8 | Y21: =IF(OR('MAPAS DE RIESGOS INHER Y RESID'!$G$18='MATRIZ DE RIESGOS DE SST'!X21,X21<'MAPAS DE RIESGOS INHER Y RESID'!$G$16+1),'MAPAS DE RIESGOS INHER Y RESID'!$M$19,IF(OR('MAPAS DE RIESGOS INHER Y RESID'!$H$17='MATRIZ DE RIESGOS DE SST'!X21,X21<'MAPAS DE RIESGOS INHER Y RESID'!$I$18+1),'MAPAS DE RIESGOS INHER Y RESID'!$M$18,IF(OR('MAPAS DE RIESGOS INHER Y RESID'!$I$17='MATRIZ DE RIESGOS DE SST'!X21,X21<'MAPAS DE RIESGOS INHER Y RESID'!$J$17+1),'MAPAS DE RIESGOS INHER Y RESID'!$M$17,'MAPAS DE RIESGOS INHER Y RESID'!$M$16))) -> BAJO | Z21: =VLOOKUP('MATRIZ DE RIESGOS DE SST'!Y21,'TABLA DE CRITERIOS'!$A$25:$B$28,2,FALSE) -> Mantener los controles existentes, si se tiene la certeza de que se están cumpliendo los requisitos legales vigentes; en caso contrario, se debe establecer un plan de acción para darle cumplimiento a dichos requisitos, considerando la eliminación o sustitución, si aplica.
I22: BIOMECÁNICO: Postura prolongada mantenida | J22: *Labores en oficina en general. | K22: *Desórdenes de trauma acumulativo; lesiones del sistema músculo esquelético; fatiga; alteraciones lumbares, dorsales, cervicales y sacras; alteraciones del sistema vascular. | L22: MODERADA | M22: =VLOOKUP('MATRIZ DE RIESGOS DE SST'!L22,'MAPAS DE RIESGOS INHER Y RESID'!$E$3:$F$7,2,FALSE) -> 3 | N22: IMPORTANTE | O22: =VLOOKUP('MATRIZ DE RIESGOS DE SST'!N22,'MAPAS DE RIESGOS INHER Y RESID'!$O$3:$P$7,2,FALSE) -> 16 | P22: =+M22*O22 -> 48 | Q22: ALTO | R22: espacio adecuado de trabajo, mobiliario ergonómico (sillas, descansa pies y teclados para computador) archivadores organizadores | S22: No Aplica | T22: Hacer pausas activas durante la jornada laboral | U22: solicitar acompañamiento y evaluación de seguridad y salud en el trabajo | V22: FUERTE | W22: =VLOOKUP(V22,'MAPAS DE RIESGOS INHER Y RESID'!$E$16:$F$18,2,FALSE) -> 0.9 | X22: =P22-(P22*W22) -> 4.8 | Y22: BAJO | Z22: =VLOOKUP('MATRIZ DE RIESGOS DE SST'!Y22,'TABLA DE CRITERIOS'!$A$25:$B$28,2,FALSE) -> Mantener los controles existentes, si se tiene la certeza de que se están cumpliendo los requisitos legales vigentes; en caso contrario, se debe establecer un plan de acción para darle cumplimiento a dichos requisitos, considerando la eliminación o sustitución, si aplica.
I23: FENÓMENOS NATURALES: Arroyos | J23: *Lluvias, vendavales, tormentas eléctricas, arroyos. | K23: *Contusiones, asfixia, fracturas, amputaciones, muerte. | L23: MODERADA | M23: =VLOOKUP('MATRIZ DE RIESGOS DE SST'!L23,'MAPAS DE RIESGOS INHER Y RESID'!$E$3:$F$7,2,FALSE) -> 3 | N23: IMPORTANTE | O23: =VLOOKUP('MATRIZ DE RIESGOS DE SST'!N23,'MAPAS DE RIESGOS INHER Y RESID'!$O$3:$P$7,2,FALSE) -> 16 | P23: =+M23*O23 -> 48 | Q23: =IF(OR('MAPAS DE RIESGOS INHER Y RESID'!$G$7='MATRIZ DE RIESGOS DE SST'!P23,P23<'MAPAS DE RIESGOS INHER Y RESID'!$G$3+1),'MAPAS DE RIESGOS INHER Y RESID'!$M$6,IF(OR('MAPAS DE RIESGOS INHER Y RESID'!$H$5='MATRIZ DE RIESGOS DE SST'!P23,P23<'MAPAS DE RIESGOS INHER Y RESID'!$I$5+1),'MAPAS DE RIESGOS INHER Y RESID'!$M$5,IF(OR('MAPAS DE RIESGOS INHER Y RESID'!$I$4='MATRIZ DE RIESGOS DE SST'!P23,P23<'MAPAS DE RIESGOS INHER Y RESID'!$J$4+1),'MAPAS DE RIESGOS INHER Y RESID'!$M$4,'MAPAS DE RIESGOS INHER Y RESID'!$M$3))) -> MODERADO | R23: No Aplica. | S23: No aplica | T23: suspender actividades y resguardarse | U23: instrucción sobre medidas de seguridad y primeros auxilios | V23: MODERADA | W23: =VLOOKUP(V23,'MAPAS DE RIESGOS INHER Y RESID'!$E$16:$F$18,2,FALSE) -> 0.4 | X23: =P23-(P23*W23) -> 28.8 | Y23: BAJO | Z23: =VLOOKUP('MATRIZ DE RIESGOS DE SST'!Y23,'TABLA DE CRITERIOS'!$A$25:$B$28,2,FALSE) -> Mantener los controles existentes, si se tiene la certeza de que se están cumpliendo los requisitos legales vigentes; en caso contrario, se debe establecer un plan de acción para darle cumplimiento a dichos requisitos, considerando la eliminación o sustitución, si aplica.
I24: PÚBLICO: Agresiones de usuarios - Comunidad | J24: *Realizar tareas en campo. *Atención de público. *Atención de público, en las instaciones de la empresa, donde se encuentran las oficinas administrativas. *Disturbios públicos. *Vandalismo *Paros, manifestaciones. *Ingresar a zonas de riesgo. | K24: *Muerte, agresiones verbales y físicas, heridas, estrés laboral, pérdidas económicas. | L24: MODERADA | M24: =VLOOKUP('MATRIZ DE RIESGOS DE SST'!L24,'MAPAS DE RIESGOS INHER Y RESID'!$E$3:$F$7,2,FALSE) -> 3 | N24: IMPORTANTE | O24: =VLOOKUP('MATRIZ DE RIESGOS DE SST'!N24,'MAPAS DE RIESGOS INHER Y RESID'!$O$3:$P$7,2,FALSE) -> 16 | P24: =+M24*O24 -> 48 | Q24: =IF(OR('MAPAS DE RIESGOS INHER Y RESID'!$G$7='MATRIZ DE RIESGOS DE SST'!P24,P24<'MAPAS DE RIESGOS INHER Y RESID'!$G$3+1),'MAPAS DE RIESGOS INHER Y RESID'!$M$6,IF(OR('MAPAS DE RIESGOS INHER Y RESID'!$H$5='MATRIZ DE RIESGOS DE SST'!P24,P24<'MAPAS DE RIESGOS INHER Y RESID'!$I$5+1),'MAPAS DE RIESGOS INHER Y RESID'!$M$5,IF(OR('MAPAS DE RIESGOS INHER Y RESID'!$I$4='MATRIZ DE RIESGOS DE SST'!P24,P24<'MAPAS DE RIESGOS INHER Y RESID'!$J$4+1),'MAPAS DE RIESGOS INHER Y RESID'!$M$4,'MAPAS DE RIESGOS INHER Y RESID'!$M$3))) -> MODERADO | R24: Evaluar riesgo inminente implementando medidas de seguridad. | S24: Alejarse con precausion ante disturbio del orden publico | T24: Evitar transitar por areas con alteracion del orden publico. | U24: difundir informacion sobre lugares de disturbiosy manifestaciones Coordinar apoyo de unidades policivas para custodia y protección ante estos eventos | V24: FUERTE | W24: =VLOOKUP(V24,'MAPAS DE RIESGOS INHER Y RESID'!$E$16:$F$18,2,FALSE) -> 0.9 | X24: =P24-(P24*W24) -> 4.8 | Y24: =IF(OR('MAPAS DE RIESGOS INHER Y RESID'!$G$18='MATRIZ DE RIESGOS DE SST'!X24,X24<'MAPAS DE RIESGOS INHER Y RESID'!$G$16+1),'MAPAS DE RIESGOS INHER Y RESID'!$M$19,IF(OR('MAPAS DE RIESGOS INHER Y RESID'!$H$17='MATRIZ DE RIESGOS DE SST'!X24,X24<'MAPAS DE RIESGOS INHER Y RESID'!$I$18+1),'MAPAS DE RIESGOS INHER Y RESID'!$M$18,IF(OR('MAPAS DE RIESGOS INHER Y RESID'!$I$17='MATRIZ DE RIESGOS DE SST'!X24,X24<'MAPAS DE RIESGOS INHER Y RESID'!$J$17+1),'MAPAS DE RIESGOS INHER Y RESID'!$M$17,'MAPAS DE RIESGOS INHER Y RESID'!$M$16))) -> BAJO | Z24: =VLOOKUP('MATRIZ DE RIESGOS DE SST'!Y24,'TABLA DE CRITERIOS'!$A$25:$B$28,2,FALSE) -> Mantener los controles existentes, si se tiene la certeza de que se están cumpliendo los requisitos legales vigentes; en caso contrario, se debe establecer un plan de acción para darle cumplimiento a dichos requisitos, considerando la eliminación o sustitución, si aplica.
I25: PÚBLICO: Asalto | J25: *Realizar tareas en la calle. *Disturbios públicos. *Vandalismo *Paros, manifestaciones. *Ingresar a zonas de riesgo. *Transito de rutas por diversas zonas de la ciudad. | K25: *Muerte, agresiones verbales y físicas, heridas, estrés laboral, pérdidas económicas. | L25: MODERADA | M25: =VLOOKUP('MATRIZ DE RIESGOS DE SST'!L25,'MAPAS DE RIESGOS INHER Y RESID'!$E$3:$F$7,2,FALSE) -> 3 | N25: IMPORTANTE | O25: =VLOOKUP('MATRIZ DE RIESGOS DE SST'!N25,'MAPAS DE RIESGOS INHER Y RESID'!$O$3:$P$7,2,FALSE) -> 16 | P25: =+M25*O25 -> 48 | Q25: =IF(OR('MAPAS DE RIESGOS INHER Y RESID'!$G$7='MATRIZ DE RIESGOS DE SST'!P25,P25<'MAPAS DE RIESGOS INHER Y RESID'!$G$3+1),'MAPAS DE RIESGOS INHER Y RESID'!$M$6,IF(OR('MAPAS DE RIESGOS INHER Y RESID'!$H$5='MATRIZ DE RIESGOS DE SST'!P25,P25<'MAPAS DE RIESGOS INHER Y RESID'!$I$5+1),'MAPAS DE RIESGOS INHER Y RESID'!$M$5,IF(OR('MAPAS DE RIESGOS INHER Y RESID'!$I$4='MATRIZ DE RIESGOS DE SST'!P25,P25<'MAPAS DE RIESGOS INHER Y RESID'!$J$4+1),'MAPAS DE RIESGOS INHER Y RESID'!$M$4,'MAPAS DE RIESGOS INHER Y RESID'!$M$3))) -> MODERADO | R25: Evaluar riesgo inminente implementando medidas de seguridad. | S25: Alejarse con precausion sin llamar la atencion en caso de riesgo inminente. | T25: Evitar transitar por areas en conflicto o areas con incidencia delincuencial. | U25: difundir informacion sobre areas con incidencia delincuencial- Coordinar apoyo de unidades policivas para custodia y protección ante estos eventos | V25: FUERTE | W25: =VLOOKUP(V25,'MAPAS DE RIESGOS INHER Y RESID'!$E$16:$F$18,2,FALSE) -> 0.9 | X25: =P25-(P25*W25) -> 4.8 | Y25: =IF(OR('MAPAS DE RIESGOS INHER Y RESID'!$G$18='MATRIZ DE RIESGOS DE SST'!X25,X25<'MAPAS DE RIESGOS INHER Y RESID'!$G$16+1),'MAPAS DE RIESGOS INHER Y RESID'!$M$19,IF(OR('MAPAS DE RIESGOS INHER Y RESID'!$H$17='MATRIZ DE RIESGOS DE SST'!X25,X25<'MAPAS DE RIESGOS INHER Y RESID'!$I$18+1),'MAPAS DE RIESGOS INHER Y RESID'!$M$18,IF(OR('MAPAS DE RIESGOS INHER Y RESID'!$I$17='MATRIZ DE RIESGOS DE SST'!X25,X25<'MAPAS DE RIESGOS INHER Y RESID'!$J$17+1),'MAPAS DE RIESGOS INHER Y RESID'!$M$17,'MAPAS DE RIESGOS INHER Y RESID'!$M$16))) -> BAJO | Z25: =VLOOKUP('MATRIZ DE RIESGOS DE SST'!Y25,'TABLA DE CRITERIOS'!$A$25:$B$28,2,FALSE) -> Mantener los controles existentes, si se tiene la certeza de que se están cumpliendo los requisitos legales vigentes; en caso contrario, se debe establecer un plan de acción para darle cumplimiento a dichos requisitos, considerando la eliminación o sustitución, si aplica.
I26: SEGURIDAD: Accidentes de tránsito | J26: *Vías deterioradas. *Problemas de salud del conductor. *Excesos de velocidad. *Incumplimiento de normas y señales de tránsito. *Conducir bajo los efectos del alcohol o sustancias psicoactivas. *Actos inseguros (Salir del vehículo cuando aún no se ha detenido, sacar la cabeza y las manos por las ventanillas, viajar en el estribo o colgado en el transporte público). *Vehículos en malas condiciones de funcionamiento. *Falta de mantenimiento a vehículos. *Personas imprudentes en la vía. * Alta circulacion vehicular * Volcamiento de maquinaria amarilla en movimiento. PEATONES: *Trabajo y/o transito en zonas con trafico vehicular y/o operación de maquinaria pesada. *Cruzar las calles sin respetar las señales de trásito y semáforos. | K26: *Muerte, fracturas, contusiones, daño cervical, pérdidas económicas. | L26: MODERADA | M26: =VLOOKUP('MATRIZ DE RIESGOS DE SST'!L26,'MAPAS DE RIESGOS INHER Y RESID'!$E$3:$F$7,2,FALSE) -> 3 | N26: IMPORTANTE | O26: =VLOOKUP('MATRIZ DE RIESGOS DE SST'!N26,'MAPAS DE RIESGOS INHER Y RESID'!$O$3:$P$7,2,FALSE) -> 16 | P26: =+M26*O26 -> 48 | Q26: =IF(OR('MAPAS DE RIESGOS INHER Y RESID'!$G$7='MATRIZ DE RIESGOS DE SST'!P26,P26<'MAPAS DE RIESGOS INHER Y RESID'!$G$3+1),'MAPAS DE RIESGOS INHER Y RESID'!$M$6,IF(OR('MAPAS DE RIESGOS INHER Y RESID'!$H$5='MATRIZ DE RIESGOS DE SST'!P26,P26<'MAPAS DE RIESGOS INHER Y RESID'!$I$5+1),'MAPAS DE RIESGOS INHER Y RESID'!$M$5,IF(OR('MAPAS DE RIESGOS INHER Y RESID'!$I$4='MATRIZ DE RIESGOS DE SST'!P26,P26<'MAPAS DE RIESGOS INHER Y RESID'!$J$4+1),'MAPAS DE RIESGOS INHER Y RESID'!$M$4,'MAPAS DE RIESGOS INHER Y RESID'!$M$3))) -> MODERADO | R26: Durante los desplazamientos utilizar vehiculos con caracterirsticas mecanicas acorde al terreno, que cumplan los requisitos de transito exigidos por las autoridades de transito,soat, tecnomecanica, usar cinturon de seguridad, respetar la velocidad establecida y respetar todas las señales de transito | S26: No exceder la velocidad maxima permitida , ni exigir al conductor que lo haga, no quitarse el cinturon de seguridad mientras este en marcha,no distraerse con equipos celulares u otros mientras conduce o distraer al conductor. | T26: Abstenerse de conducir si no se encuentra en condiciones fisica y de salud para hacerlo ( sueño o cansancio) si el trayecto es muy distante , realizar pausas de descanso cada 2 horas. | U26: Capacitación sobre manejo preventivo y defensivo;normas de seguridad vial y acreditación de conductores. Realizar plan de mantenimiento preventivo y correctivo de los vehículos empresariales. | V26: FUERTE | W26: =VLOOKUP(V26,'MAPAS DE RIESGOS INHER Y RESID'!$E$16:$F$18,2,FALSE) -> 0.9 | X26: =P26-(P26*W26) -> 4.8 | Y26: =IF(OR('MAPAS DE RIESGOS INHER Y RESID'!$G$18='MATRIZ DE RIESGOS DE SST'!X26,X26<'MAPAS DE RIESGOS INHER Y RESID'!$G$16+1),'MAPAS DE RIESGOS INHER Y RESID'!$M$19,IF(OR('MAPAS DE RIESGOS INHER Y RESID'!$H$17='MATRIZ DE RIESGOS DE SST'!X26,X26<'MAPAS DE RIESGOS INHER Y RESID'!$I$18+1),'MAPAS DE RIESGOS INHER Y RESID'!$M$18,IF(OR('MAPAS DE RIESGOS INHER Y RESID'!$I$17='MATRIZ DE RIESGOS DE SST'!X26,X26<'MAPAS DE RIESGOS INHER Y RESID'!$J$17+1),'MAPAS DE RIESGOS INHER Y RESID'!$M$17,'MAPAS DE RIESGOS INHER Y RESID'!$M$16))) -> BAJO | Z26: =VLOOKUP('MATRIZ DE RIESGOS DE SST'!Y26,'TABLA DE CRITERIOS'!$A$25:$B$28,2,FALSE) -> Mantener los controles existentes, si se tiene la certeza de que se están cumpliendo los requisitos legales vigentes; en caso contrario, se debe establecer un plan de acción para darle cumplimiento a dichos requisitos, considerando la eliminación o sustitución, si aplica.
I27: SEGURIDAD: Locativo-Caída de objetos | J27: *Falta de orden y aseo. *Estructuras sin anclajes. *Cargas suspendidas por maquinarias. *Alcanzar objetos, herramientas o materiales, almacenados en estantes. *Herramientas ubicadas en niveles superiores. | K27: *Fracturas, contusiones. | L27: BAJA | M27: =VLOOKUP('MATRIZ DE RIESGOS DE SST'!L27,'MAPAS DE RIESGOS INHER Y RESID'!$E$3:$F$7,2,FALSE) -> 2 | N27: IMPORTANTE | O27: =VLOOKUP('MATRIZ DE RIESGOS DE SST'!N27,'MAPAS DE RIESGOS INHER Y RESID'!$O$3:$P$7,2,FALSE) -> 16 | P27: =+M27*O27 -> 32 | Q27: =IF(OR('MAPAS DE RIESGOS INHER Y RESID'!$G$7='MATRIZ DE RIESGOS DE SST'!P27,P27<'MAPAS DE RIESGOS INHER Y RESID'!$G$3+1),'MAPAS DE RIESGOS INHER Y RESID'!$M$6,IF(OR('MAPAS DE RIESGOS INHER Y RESID'!$H$5='MATRIZ DE RIESGOS DE SST'!P27,P27<'MAPAS DE RIESGOS INHER Y RESID'!$I$5+1),'MAPAS DE RIESGOS INHER Y RESID'!$M$5,IF(OR('MAPAS DE RIESGOS INHER Y RESID'!$I$4='MATRIZ DE RIESGOS DE SST'!P27,P27<'MAPAS DE RIESGOS INHER Y RESID'!$J$4+1),'MAPAS DE RIESGOS INHER Y RESID'!$M$4,'MAPAS DE RIESGOS INHER Y RESID'!$M$3))) -> MODERADO | R27: Durante las labores de supervición y control a la seguridad fisicas de instalaciones, realizar inspeccion visual a las areas de transito, identificando factores de riesgo en los niveles superiores, trabajos locativos o electricos en altura con riesgo de caida de herramientas, maquinaria o luminarias. | S27: evitar transitar por areas de riesgo donde se esten adelantando trabajos en alturas, mantenimientos de luminarias o locativos que puedan generar caida de objetos, materiales uo herramientas que puedan llegar a causar lexiones, fracturas o contusiones | T27: Uso de elementos protectores como cascos, gafas y calzado antideslizante. | U27: Capacitacion sobre evaluación del riesgo y medidas de autoprotección en riesgos laborales | V27: MODERADA | W27: =VLOOKUP(V27,'MAPAS DE RIESGOS INHER Y RESID'!$E$16:$F$18,2,FALSE) -> 0.4 | X27: =P27-(P27*W27) -> 19.2 | Y27: BAJO | Z27: =VLOOKUP('MATRIZ DE RIESGOS DE SST'!Y27,'TABLA DE CRITERIOS'!$A$25:$B$28,2,FALSE) -> Mantener los controles existentes, si se tiene la certeza de que se están cumpliendo los requisitos legales vigentes; en caso contrario, se debe establecer un plan de acción para darle cumplimiento a dichos requisitos, considerando la eliminación o sustitución, si aplica.
I28: SEGURIDAD: Locativo-Condiciones de orden y aseo | J28: *Desorden. *Realizar actividades de campo. *Transitar por las instalaciones. *Obstáculos en el piso. | K28: *Golpes, heridas, contusiones, fracturas, esguinces, luxaciones, muerte. | L28: BAJA | M28: =VLOOKUP('MATRIZ DE RIESGOS DE SST'!L28,'MAPAS DE RIESGOS INHER Y RESID'!$E$3:$F$7,2,FALSE) -> 2 | N28: LEVE | O28: =VLOOKUP('MATRIZ DE RIESGOS DE SST'!N28,'MAPAS DE RIESGOS INHER Y RESID'!$O$3:$P$7,2,FALSE) -> 4 | P28: =+M28*O28 -> 8 | Q28: =IF(OR('MAPAS DE RIESGOS INHER Y RESID'!$G$7='MATRIZ DE RIESGOS DE SST'!P28,P28<'MAPAS DE RIESGOS INHER Y RESID'!$G$3+1),'MAPAS DE RIESGOS INHER Y RESID'!$M$6,IF(OR('MAPAS DE RIESGOS INHER Y RESID'!$H$5='MATRIZ DE RIESGOS DE SST'!P28,P28<'MAPAS DE RIESGOS INHER Y RESID'!$I$5+1),'MAPAS DE RIESGOS INHER Y RESID'!$M$5,IF(OR('MAPAS DE RIESGOS INHER Y RESID'!$I$4='MATRIZ DE RIESGOS DE SST'!P28,P28<'MAPAS DE RIESGOS INHER Y RESID'!$J$4+1),'MAPAS DE RIESGOS INHER Y RESID'!$M$4,'MAPAS DE RIESGOS INHER Y RESID'!$M$3))) -> BAJO | R28: Durante las labores de supervición y control a la seguridad fisicas de instalaciones, realizar una inspeccion visual a las areas por donde va a transitar identificando factores de riesgo como herramientas, materiales o tendidos electricos en el piso, que puedan ocacionar caidas o lesiones. | S28: evitar areas de riesgo donde se esten adelantando trabajos mecanicos o trabajos de mantenimiento de maquinaria que puedan provocar accidentes . | T28: Uso de elementos protectores como cascos, gafas y calzado antideslizante. | U28: Capacitacion sobre evaluación del riesgo y medidas de autoprotección en riesgos laborales | V28: MODERADA | W28: =VLOOKUP(V28,'MAPAS DE RIESGOS INHER Y RESID'!$E$16:$F$18,2,FALSE) -> 0.4 | X28: =P28-(P28*W28) -> 4.8 | Y28: =IF(OR('MAPAS DE RIESGOS INHER Y RESID'!$G$18='MATRIZ DE RIESGOS DE SST'!X28,X28<'MAPAS DE RIESGOS INHER Y RESID'!$G$16+1),'MAPAS DE RIESGOS INHER Y RESID'!$M$19,IF(OR('MAPAS DE RIESGOS INHER Y RESID'!$H$17='MATRIZ DE RIESGOS DE SST'!X28,X28<'MAPAS DE RIESGOS INHER Y RESID'!$I$18+1),'MAPAS DE RIESGOS INHER Y RESID'!$M$18,IF(OR('MAPAS DE RIESGOS INHER Y RESID'!$I$17='MATRIZ DE RIESGOS DE SST'!X28,X28<'MAPAS DE RIESGOS INHER Y RESID'!$J$17+1),'MAPAS DE RIESGOS INHER Y RESID'!$M$17,'MAPAS DE RIESGOS INHER Y RESID'!$M$16))) -> BAJO | Z28: =VLOOKUP('MATRIZ DE RIESGOS DE SST'!Y28,'TABLA DE CRITERIOS'!$A$25:$B$28,2,FALSE) -> Mantener los controles existentes, si se tiene la certeza de que se están cumpliendo los requisitos legales vigentes; en caso contrario, se debe establecer un plan de acción para darle cumplimiento a dichos requisitos, considerando la eliminación o sustitución, si aplica.
I29: SEGURIDAD: Locativo-Superficie de trabajo irregular, deslizante, con diferencia de nivel | J29: *Desnivel en el suelo. *Desorden. *Realizar actividades de campo. *Subir y bajar escaleras. *Subir y bajar estribos *Transitar por las instalaciones. *Obstáculos en el piso. *Piso resbaloso. | K29: *Golpes, heridas, contusiones, fracturas, esguinces, luxaciones, traumas del sistema osteomuscular, heridas, muerte. | L29: BAJA | M29: =VLOOKUP('MATRIZ DE RIESGOS DE SST'!L29,'MAPAS DE RIESGOS INHER Y RESID'!$E$3:$F$7,2,FALSE) -> 2 | N29: LEVE | O29: =VLOOKUP('MATRIZ DE RIESGOS DE SST'!N29,'MAPAS DE RIESGOS INHER Y RESID'!$O$3:$P$7,2,FALSE) -> 4 | P29: =+M29*O29 -> 8 | Q29: =IF(OR('MAPAS DE RIESGOS INHER Y RESID'!$G$7='MATRIZ DE RIESGOS DE SST'!P29,P29<'MAPAS DE RIESGOS INHER Y RESID'!$G$3+1),'MAPAS DE RIESGOS INHER Y RESID'!$M$6,IF(OR('MAPAS DE RIESGOS INHER Y RESID'!$H$5='MATRIZ DE RIESGOS DE SST'!P29,P29<'MAPAS DE RIESGOS INHER Y RESID'!$I$5+1),'MAPAS DE RIESGOS INHER Y RESID'!$M$5,IF(OR('MAPAS DE RIESGOS INHER Y RESID'!$I$4='MATRIZ DE RIESGOS DE SST'!P29,P29<'MAPAS DE RIESGOS INHER Y RESID'!$J$4+1),'MAPAS DE RIESGOS INHER Y RESID'!$M$4,'MAPAS DE RIESGOS INHER Y RESID'!$M$3))) -> BAJO | R29: Durante las labores de supervición y control a la seguridad fisicas de instalaciones, realizar una inspeccion visual a las areas por donde va a transitar identificando factores de riesgo que puedan ocacionar caidas o lesiones. | S29: evitar areas de riesgo como son pisos humedos, superficies deslizantes, irregulares y demas areas con condiciones de terreno que puedan causar caidas, luxasiones u traumas osteomusculares. | T29: Uso de elementos protectores como cascos, gafas y calzado antideslizante. | U29: Capacitacion sobre evaluación del riesgo y medidas de autoprotección en riesgos laborales | V29: MODERADA | W29: =VLOOKUP(V29,'MAPAS DE RIESGOS INHER Y RESID'!$E$16:$F$18,2,FALSE) -> 0.4 | X29: =P29-(P29*W29) -> 4.8 | Y29: =IF(OR('MAPAS DE RIESGOS INHER Y RESID'!$G$18='MATRIZ DE RIESGOS DE SST'!X29,X29<'MAPAS DE RIESGOS INHER Y RESID'!$G$16+1),'MAPAS DE RIESGOS INHER Y RESID'!$M$19,IF(OR('MAPAS DE RIESGOS INHER Y RESID'!$H$17='MATRIZ DE RIESGOS DE SST'!X29,X29<'MAPAS DE RIESGOS INHER Y RESID'!$I$18+1),'MAPAS DE RIESGOS INHER Y RESID'!$M$18,IF(OR('MAPAS DE RIESGOS INHER Y RESID'!$I$17='MATRIZ DE RIESGOS DE SST'!X29,X29<'MAPAS DE RIESGOS INHER Y RESID'!$J$17+1),'MAPAS DE RIESGOS INHER Y RESID'!$M$17,'MAPAS DE RIESGOS INHER Y RESID'!$M$16))) -> BAJO | Z29: =VLOOKUP('MATRIZ DE RIESGOS DE SST'!Y29,'TABLA DE CRITERIOS'!$A$25:$B$28,2,FALSE) -> Mantener los controles existentes, si se tiene la certeza de que se están cumpliendo los requisitos legales vigentes; en caso contrario, se debe establecer un plan de acción para darle cumplimiento a dichos requisitos, considerando la eliminación o sustitución, si aplica.

Sheet UNIVERSO DE RIESGOS DE SST 
A1: FACTOR DE RIESGO (PELIGRO) | B1: CAUSA | C1: CONSECUENCIA
A2: BIOLÓGICO: Contacto con plantas urticantes | B2: *Actividades realizadas en campo donde hay maleza. *Contacto con plantas urticantes. | C2: *Dermatosis, reacciones alérgicas, enfermedades infecto contagiosas, alteraciones en los diferentes sistemas.
A3: BIOLÓGICO: Fluidos o excrementos | B3: *Contacto con fluídos corporales y secreciones. | C3: *Dermatosis, reacciones alérgicas, enfermedades infecto contagiosas, alteraciones en los diferentes sistemas.
A4: BIOLÓGICO: Microorganismos (Virus y bacterias) | B4: *Contacto con fluídos corporales y secreciones. *Ingestión de alimentos/agua contaminados. *Retención de orina o heces por desempeño laboral fuera de la sede de la empresa. *Realizar labores de campo de lugares de riesgo de enfermedades de salud pública. *Contacto con superficies contaminadas por manipulacion de residuos solidos ordinarios. *Contacto con superficies contaminadas por manipulacion de residuos peligrosos. *Trabajo en ambientes contaminados por disposicion de residuos solidos. *Recoleccion y manipulacion de redisuos solidos. *Exposicion a aguas residuales. *Trabajo cerca de lagunas de lixiviados. Contacto con lixiviado tratado. | C4: *Dermatosis, reacciones alérgicas, enfermedades infecto contagiosas, alteraciones en los diferentes sistemas, muerte.
A5: BIOLÓGICO: Microorganismos (Virus-COVID-19) | B5: *Contacto directo entre personas portadoras del virus CODIV-19 u objetos contaminados. *Contacto con fluídos corporales y secreciones. | C5: *IRA-Infección Respiratoria Aguda de leve a grave, neumonia, alteraciones en los diferentes sistemas, muerte.
